test_user_detection_false (T3_US01.US01) ... FAIL
test_user_detection_true (T3_US01.US01) ... ok
test_turn_light_off_occupancy (T3_US02.US02) ... FAIL
test_turn_light_on_occupancy (T3_US02.US02) ... ok
test_light_off_no_user (T3_US03.US03) ... ok
test_light_off_user (T3_US03.US03) ... ok
test_temperature_reading (T3_US04.US04) ... ok
test_window_closed_temperature_in_range (T3_US04.US04) ... ok
test_window_closed_temperature_out_of_range (T3_US04.US04) ... ok
test_window_open_temperature_in_range (T3_US04.US04) ... ok
test_buzzer_off_gas_detected (T3_US05.US05) ... ok
test_buzzer_on_gas_detected (T3_US05.US05) ... ok

======================================================================
FAIL: test_user_detection_false (T3_US01.US01)
----------------------------------------------------------------------
Traceback (most recent call last):
  File "C:\Users\Michelangelo\AppData\Local\Programs\Python\Python310\lib\unittest\mock.py", line 1369, in patched
    return func(*newargs, **newkeywargs)
  File "C:\Users\Michelangelo\CS\Python\tasks_analysis\test\T3_US01.py", line 21, in test_user_detection_false
    self.assertFalse(occ)
AssertionError: True is not false

======================================================================
FAIL: test_turn_light_off_occupancy (T3_US02.US02)
----------------------------------------------------------------------
Traceback (most recent call last):
  File "C:\Users\Michelangelo\AppData\Local\Programs\Python\Python310\lib\unittest\mock.py", line 1369, in patched
    return func(*newargs, **newkeywargs)
  File "C:\Users\Michelangelo\CS\Python\tasks_analysis\test\T3_US02.py", line 23, in test_turn_light_off_occupancy
    self.assertFalse(light_on)
AssertionError: True is not false

----------------------------------------------------------------------
Ran 12 tests in 36.223s

FAILED (failures=2)
