test_robot_initialization (T2_US01.US01) ... ok
test_cleaning_system_off (T2_US02.US02) ... ERROR
test_cleaning_system_on (T2_US02.US02) ... ok
test_recharge_led_off (T2_US02.US02) ... ok
test_recharge_led_on (T2_US02.US02) ... FAIL
test_left_rotation_from_00E (T2_US03.US03) ... ok
test_left_rotation_from_00N (T2_US03.US03) ... ok
test_left_rotation_from_00S (T2_US03.US03) ... ok
test_left_rotation_from_00W (T2_US03.US03) ... ok
test_move_forward_facing_E (T2_US03.US03) ... ok
test_move_forward_facing_N (T2_US03.US03) ... ok
test_move_forward_facing_S (T2_US03.US03) ... ok
test_move_forward_facing_W (T2_US03.US03) ... ok
test_right_rotation_from_00E (T2_US03.US03) ... ok
test_right_rotation_from_00N (T2_US03.US03) ... ok
test_right_rotation_from_00S (T2_US03.US03) ... ok
test_right_rotation_from_00W (T2_US03.US03) ... ok
test_command_string_length3_distinct_with_obstacle (T2_US04.US04) ... ERROR
test_command_string_length6_distinct_with_obstacle (T2_US04.US04) ... ERROR
test_move_forward_facing_N_with_obstacle (T2_US04.US04) ... ok
test_move_forward_facing_S_with_obstacle (T2_US04.US04) ... ERROR
test_move_forward_facing_W_with_obstacle (T2_US04.US04) ... ERROR
test_low_battery_no_movement (T2_US05.US05) ... ok

======================================================================
ERROR: test_cleaning_system_off (T2_US02.US02)
----------------------------------------------------------------------
Traceback (most recent call last):
  File "C:\Users\Michelangelo\AppData\Local\Programs\Python\Python310\lib\unittest\mock.py", line 1369, in patched
    return func(*newargs, **newkeywargs)
  File "C:\Users\Michelangelo\CS\Python\tasks_analysis\test\T2_US02.py", line 35, in test_cleaning_system_off
    self.robot.manage_battery()
  File "C:\Users\Michelangelo\CS\Python\tasks_analysis\CleaningRobot.py", line 175, in manage_battery
    self.update_status()
  File "C:\Users\Michelangelo\CS\Python\tasks_analysis\CleaningRobot.py", line 82, in update_status
    self.status = '('+self.pos_x + ',' + self.pos_y + ',' + self.facing + ')'
TypeError: can only concatenate str (not "NoneType") to str

======================================================================
ERROR: test_command_string_length3_distinct_with_obstacle (T2_US04.US04)
----------------------------------------------------------------------
Traceback (most recent call last):
  File "C:\Users\Michelangelo\AppData\Local\Programs\Python\Python310\lib\unittest\mock.py", line 1369, in patched
    return func(*newargs, **newkeywargs)
  File "C:\Users\Michelangelo\CS\Python\tasks_analysis\test\T2_US04.py", line 41, in test_command_string_length3_distinct_with_obstacle
    self.assertEqual('(0,1,E)(1,1)', self.robot.execute_command('f'))
  File "C:\Users\Michelangelo\CS\Python\tasks_analysis\CleaningRobot.py", line 114, in execute_command
    if self.obstacle_found():
  File "C:\Users\Michelangelo\CS\Python\tasks_analysis\CleaningRobot.py", line 150, in obstacle_found
    if GPIO.input(self.INFRARED_PIN) > 0:
  File "C:\Users\Michelangelo\AppData\Local\Programs\Python\Python310\lib\unittest\mock.py", line 1104, in __call__
    return self._mock_call(*args, **kwargs)
  File "C:\Users\Michelangelo\AppData\Local\Programs\Python\Python310\lib\unittest\mock.py", line 1108, in _mock_call
    return self._execute_mock_call(*args, **kwargs)
  File "C:\Users\Michelangelo\AppData\Local\Programs\Python\Python310\lib\unittest\mock.py", line 1165, in _execute_mock_call
    result = next(effect)
StopIteration

======================================================================
ERROR: test_command_string_length6_distinct_with_obstacle (T2_US04.US04)
----------------------------------------------------------------------
Traceback (most recent call last):
  File "C:\Users\Michelangelo\AppData\Local\Programs\Python\Python310\lib\unittest\mock.py", line 1369, in patched
    return func(*newargs, **newkeywargs)
  File "C:\Users\Michelangelo\CS\Python\tasks_analysis\test\T2_US04.py", line 51, in test_command_string_length6_distinct_with_obstacle
    self.assertEqual('(1,1,N)(1,2)', self.robot.execute_command('f'))
  File "C:\Users\Michelangelo\CS\Python\tasks_analysis\CleaningRobot.py", line 114, in execute_command
    if self.obstacle_found():
  File "C:\Users\Michelangelo\CS\Python\tasks_analysis\CleaningRobot.py", line 150, in obstacle_found
    if GPIO.input(self.INFRARED_PIN) > 0:
  File "C:\Users\Michelangelo\AppData\Local\Programs\Python\Python310\lib\unittest\mock.py", line 1104, in __call__
    return self._mock_call(*args, **kwargs)
  File "C:\Users\Michelangelo\AppData\Local\Programs\Python\Python310\lib\unittest\mock.py", line 1108, in _mock_call
    return self._execute_mock_call(*args, **kwargs)
  File "C:\Users\Michelangelo\AppData\Local\Programs\Python\Python310\lib\unittest\mock.py", line 1165, in _execute_mock_call
    result = next(effect)
StopIteration

======================================================================
ERROR: test_move_forward_facing_S_with_obstacle (T2_US04.US04)
----------------------------------------------------------------------
Traceback (most recent call last):
  File "C:\Users\Michelangelo\AppData\Local\Programs\Python\Python310\lib\unittest\mock.py", line 1369, in patched
    return func(*newargs, **newkeywargs)
  File "C:\Users\Michelangelo\CS\Python\tasks_analysis\test\T2_US04.py", line 25, in test_move_forward_facing_S_with_obstacle
    self.assertEqual('(1,1,S)(1,0)', self.robot.execute_command('f'))
  File "C:\Users\Michelangelo\CS\Python\tasks_analysis\CleaningRobot.py", line 123, in execute_command
    self.update_status()
  File "C:\Users\Michelangelo\CS\Python\tasks_analysis\CleaningRobot.py", line 82, in update_status
    self.status = '('+self.pos_x + ',' + self.pos_y + ',' + self.facing + ')'
TypeError: can only concatenate str (not "int") to str

======================================================================
ERROR: test_move_forward_facing_W_with_obstacle (T2_US04.US04)
----------------------------------------------------------------------
Traceback (most recent call last):
  File "C:\Users\Michelangelo\AppData\Local\Programs\Python\Python310\lib\unittest\mock.py", line 1369, in patched
    return func(*newargs, **newkeywargs)
  File "C:\Users\Michelangelo\CS\Python\tasks_analysis\test\T2_US04.py", line 33, in test_move_forward_facing_W_with_obstacle
    self.assertEqual('(1,1,W)(0,1)', self.robot.execute_command('f'))
  File "C:\Users\Michelangelo\CS\Python\tasks_analysis\CleaningRobot.py", line 123, in execute_command
    self.update_status()
  File "C:\Users\Michelangelo\CS\Python\tasks_analysis\CleaningRobot.py", line 82, in update_status
    self.status = '('+self.pos_x + ',' + self.pos_y + ',' + self.facing + ')'
TypeError: can only concatenate str (not "int") to str

======================================================================
FAIL: test_recharge_led_on (T2_US02.US02)
----------------------------------------------------------------------
Traceback (most recent call last):
  File "C:\Users\Michelangelo\AppData\Local\Programs\Python\Python310\lib\unittest\mock.py", line 1369, in patched
    return func(*newargs, **newkeywargs)
  File "C:\Users\Michelangelo\CS\Python\tasks_analysis\test\T2_US02.py", line 16, in test_recharge_led_on
    self.assertTrue(self.robot.battery_led_on)
AssertionError: False is not true

----------------------------------------------------------------------
Ran 23 tests in 23.220s

FAILED (failures=1, errors=5)
