test_robot_initialization (T2_US01.US01) ... ERROR
test_cleaning_system_off (T2_US02.US02) ... ok
test_cleaning_system_on (T2_US02.US02) ... ok
test_recharge_led_off (T2_US02.US02) ... ok
test_recharge_led_on (T2_US02.US02) ... ok
test_left_rotation_from_00E (T2_US03.US03) ... ok
test_left_rotation_from_00N (T2_US03.US03) ... ok
test_left_rotation_from_00S (T2_US03.US03) ... ok
test_left_rotation_from_00W (T2_US03.US03) ... ok
test_move_forward_facing_E (T2_US03.US03) ... ERROR
test_move_forward_facing_N (T2_US03.US03) ... ERROR
test_move_forward_facing_S (T2_US03.US03) ... ERROR
test_move_forward_facing_W (T2_US03.US03) ... ERROR
test_right_rotation_from_00E (T2_US03.US03) ... ok
test_right_rotation_from_00N (T2_US03.US03) ... ok
test_right_rotation_from_00S (T2_US03.US03) ... ok
test_right_rotation_from_00W (T2_US03.US03) ... ok
test_command_string_length3_distinct_with_obstacle (T2_US04.US04) ... ERROR
test_command_string_length6_distinct_with_obstacle (T2_US04.US04) ... ERROR
test_move_forward_facing_N_with_obstacle (T2_US04.US04) ... ERROR
test_move_forward_facing_S_with_obstacle (T2_US04.US04) ... ERROR
test_move_forward_facing_W_with_obstacle (T2_US04.US04) ... ERROR
test_low_battery_no_movement (T2_US05.US05) ... FAIL

======================================================================
ERROR: test_robot_initialization (T2_US01.US01)
----------------------------------------------------------------------
Traceback (most recent call last):
  File "C:\Users\Michelangelo\CS\Python\tasks_analysis\test\T2_US01.py", line 9, in test_robot_initialization
    self.assertEqual('(0,0,N)', robot.robot_status())
  File "C:\Users\Michelangelo\CS\Python\tasks_analysis\CleaningRobot.py", line 71, in robot_status
    if self.obstacle_found():
  File "C:\Users\Michelangelo\CS\Python\tasks_analysis\CleaningRobot.py", line 155, in obstacle_found
    return GPIO.input(self.INFRARED_PIN) > 0
TypeError: '>' not supported between instances of 'NoneType' and 'int'

======================================================================
ERROR: test_move_forward_facing_E (T2_US03.US03)
----------------------------------------------------------------------
Traceback (most recent call last):
  File "C:\Users\Michelangelo\AppData\Local\Programs\Python\Python310\lib\unittest\mock.py", line 1369, in patched
    return func(*newargs, **newkeywargs)
  File "C:\Users\Michelangelo\CS\Python\tasks_analysis\test\T2_US03.py", line 74, in test_move_forward_facing_E
    self.assertEqual('(1,0,E)', self.robot.execute_command('f'))
  File "C:\Users\Michelangelo\CS\Python\tasks_analysis\CleaningRobot.py", line 148, in execute_command
    return self.robot_status()
  File "C:\Users\Michelangelo\CS\Python\tasks_analysis\CleaningRobot.py", line 71, in robot_status
    if self.obstacle_found():
  File "C:\Users\Michelangelo\CS\Python\tasks_analysis\CleaningRobot.py", line 155, in obstacle_found
    return GPIO.input(self.INFRARED_PIN) > 0
  File "C:\Users\Michelangelo\AppData\Local\Programs\Python\Python310\lib\unittest\mock.py", line 1104, in __call__
    return self._mock_call(*args, **kwargs)
  File "C:\Users\Michelangelo\AppData\Local\Programs\Python\Python310\lib\unittest\mock.py", line 1108, in _mock_call
    return self._execute_mock_call(*args, **kwargs)
  File "C:\Users\Michelangelo\AppData\Local\Programs\Python\Python310\lib\unittest\mock.py", line 1165, in _execute_mock_call
    result = next(effect)
StopIteration

======================================================================
ERROR: test_move_forward_facing_N (T2_US03.US03)
----------------------------------------------------------------------
Traceback (most recent call last):
  File "C:\Users\Michelangelo\AppData\Local\Programs\Python\Python310\lib\unittest\mock.py", line 1369, in patched
    return func(*newargs, **newkeywargs)
  File "C:\Users\Michelangelo\CS\Python\tasks_analysis\test\T2_US03.py", line 68, in test_move_forward_facing_N
    self.assertEqual('(0,1,N)', self.robot.execute_command('f'))
  File "C:\Users\Michelangelo\CS\Python\tasks_analysis\CleaningRobot.py", line 148, in execute_command
    return self.robot_status()
  File "C:\Users\Michelangelo\CS\Python\tasks_analysis\CleaningRobot.py", line 71, in robot_status
    if self.obstacle_found():
  File "C:\Users\Michelangelo\CS\Python\tasks_analysis\CleaningRobot.py", line 155, in obstacle_found
    return GPIO.input(self.INFRARED_PIN) > 0
  File "C:\Users\Michelangelo\AppData\Local\Programs\Python\Python310\lib\unittest\mock.py", line 1104, in __call__
    return self._mock_call(*args, **kwargs)
  File "C:\Users\Michelangelo\AppData\Local\Programs\Python\Python310\lib\unittest\mock.py", line 1108, in _mock_call
    return self._execute_mock_call(*args, **kwargs)
  File "C:\Users\Michelangelo\AppData\Local\Programs\Python\Python310\lib\unittest\mock.py", line 1165, in _execute_mock_call
    result = next(effect)
StopIteration

======================================================================
ERROR: test_move_forward_facing_S (T2_US03.US03)
----------------------------------------------------------------------
Traceback (most recent call last):
  File "C:\Users\Michelangelo\AppData\Local\Programs\Python\Python310\lib\unittest\mock.py", line 1369, in patched
    return func(*newargs, **newkeywargs)
  File "C:\Users\Michelangelo\CS\Python\tasks_analysis\test\T2_US03.py", line 82, in test_move_forward_facing_S
    self.assertEqual('(1,0,S)', self.robot.execute_command('f'))
  File "C:\Users\Michelangelo\CS\Python\tasks_analysis\CleaningRobot.py", line 148, in execute_command
    return self.robot_status()
  File "C:\Users\Michelangelo\CS\Python\tasks_analysis\CleaningRobot.py", line 71, in robot_status
    if self.obstacle_found():
  File "C:\Users\Michelangelo\CS\Python\tasks_analysis\CleaningRobot.py", line 155, in obstacle_found
    return GPIO.input(self.INFRARED_PIN) > 0
  File "C:\Users\Michelangelo\AppData\Local\Programs\Python\Python310\lib\unittest\mock.py", line 1104, in __call__
    return self._mock_call(*args, **kwargs)
  File "C:\Users\Michelangelo\AppData\Local\Programs\Python\Python310\lib\unittest\mock.py", line 1108, in _mock_call
    return self._execute_mock_call(*args, **kwargs)
  File "C:\Users\Michelangelo\AppData\Local\Programs\Python\Python310\lib\unittest\mock.py", line 1165, in _execute_mock_call
    result = next(effect)
StopIteration

======================================================================
ERROR: test_move_forward_facing_W (T2_US03.US03)
----------------------------------------------------------------------
Traceback (most recent call last):
  File "C:\Users\Michelangelo\AppData\Local\Programs\Python\Python310\lib\unittest\mock.py", line 1369, in patched
    return func(*newargs, **newkeywargs)
  File "C:\Users\Michelangelo\CS\Python\tasks_analysis\test\T2_US03.py", line 90, in test_move_forward_facing_W
    self.assertEqual('(0,1,W)', self.robot.execute_command('f'))
  File "C:\Users\Michelangelo\CS\Python\tasks_analysis\CleaningRobot.py", line 148, in execute_command
    return self.robot_status()
  File "C:\Users\Michelangelo\CS\Python\tasks_analysis\CleaningRobot.py", line 71, in robot_status
    if self.obstacle_found():
  File "C:\Users\Michelangelo\CS\Python\tasks_analysis\CleaningRobot.py", line 155, in obstacle_found
    return GPIO.input(self.INFRARED_PIN) > 0
  File "C:\Users\Michelangelo\AppData\Local\Programs\Python\Python310\lib\unittest\mock.py", line 1104, in __call__
    return self._mock_call(*args, **kwargs)
  File "C:\Users\Michelangelo\AppData\Local\Programs\Python\Python310\lib\unittest\mock.py", line 1108, in _mock_call
    return self._execute_mock_call(*args, **kwargs)
  File "C:\Users\Michelangelo\AppData\Local\Programs\Python\Python310\lib\unittest\mock.py", line 1165, in _execute_mock_call
    result = next(effect)
StopIteration

======================================================================
ERROR: test_command_string_length3_distinct_with_obstacle (T2_US04.US04)
----------------------------------------------------------------------
Traceback (most recent call last):
  File "C:\Users\Michelangelo\AppData\Local\Programs\Python\Python310\lib\unittest\mock.py", line 1369, in patched
    return func(*newargs, **newkeywargs)
  File "C:\Users\Michelangelo\CS\Python\tasks_analysis\test\T2_US04.py", line 41, in test_command_string_length3_distinct_with_obstacle
    self.assertEqual('(0,1,E)(1,1)', self.robot.execute_command('f'))
  File "C:\Users\Michelangelo\CS\Python\tasks_analysis\CleaningRobot.py", line 105, in execute_command
    self.manage_battery()
  File "C:\Users\Michelangelo\CS\Python\tasks_analysis\CleaningRobot.py", line 193, in manage_battery
    charge = self.get_battery_charge_state()
  File "C:\Users\Michelangelo\CS\Python\tasks_analysis\CleaningRobot.py", line 180, in get_battery_charge_state
    ibs = GPIO.input(self.BATTERY_PIN)  # In percent
  File "C:\Users\Michelangelo\AppData\Local\Programs\Python\Python310\lib\unittest\mock.py", line 1104, in __call__
    return self._mock_call(*args, **kwargs)
  File "C:\Users\Michelangelo\AppData\Local\Programs\Python\Python310\lib\unittest\mock.py", line 1108, in _mock_call
    return self._execute_mock_call(*args, **kwargs)
  File "C:\Users\Michelangelo\AppData\Local\Programs\Python\Python310\lib\unittest\mock.py", line 1165, in _execute_mock_call
    result = next(effect)
StopIteration

======================================================================
ERROR: test_command_string_length6_distinct_with_obstacle (T2_US04.US04)
----------------------------------------------------------------------
Traceback (most recent call last):
  File "C:\Users\Michelangelo\AppData\Local\Programs\Python\Python310\lib\unittest\mock.py", line 1369, in patched
    return func(*newargs, **newkeywargs)
  File "C:\Users\Michelangelo\CS\Python\tasks_analysis\test\T2_US04.py", line 49, in test_command_string_length6_distinct_with_obstacle
    self.robot.execute_command('f')
  File "C:\Users\Michelangelo\CS\Python\tasks_analysis\CleaningRobot.py", line 148, in execute_command
    return self.robot_status()
  File "C:\Users\Michelangelo\CS\Python\tasks_analysis\CleaningRobot.py", line 71, in robot_status
    if self.obstacle_found():
  File "C:\Users\Michelangelo\CS\Python\tasks_analysis\CleaningRobot.py", line 155, in obstacle_found
    return GPIO.input(self.INFRARED_PIN) > 0
  File "C:\Users\Michelangelo\AppData\Local\Programs\Python\Python310\lib\unittest\mock.py", line 1104, in __call__
    return self._mock_call(*args, **kwargs)
  File "C:\Users\Michelangelo\AppData\Local\Programs\Python\Python310\lib\unittest\mock.py", line 1108, in _mock_call
    return self._execute_mock_call(*args, **kwargs)
  File "C:\Users\Michelangelo\AppData\Local\Programs\Python\Python310\lib\unittest\mock.py", line 1165, in _execute_mock_call
    result = next(effect)
StopIteration

======================================================================
ERROR: test_move_forward_facing_N_with_obstacle (T2_US04.US04)
----------------------------------------------------------------------
Traceback (most recent call last):
  File "C:\Users\Michelangelo\AppData\Local\Programs\Python\Python310\lib\unittest\mock.py", line 1369, in patched
    return func(*newargs, **newkeywargs)
  File "C:\Users\Michelangelo\CS\Python\tasks_analysis\test\T2_US04.py", line 17, in test_move_forward_facing_N_with_obstacle
    self.assertEqual('(0,0,N)(0,1)', self.robot.execute_command('f'))
  File "C:\Users\Michelangelo\CS\Python\tasks_analysis\CleaningRobot.py", line 148, in execute_command
    return self.robot_status()
  File "C:\Users\Michelangelo\CS\Python\tasks_analysis\CleaningRobot.py", line 71, in robot_status
    if self.obstacle_found():
  File "C:\Users\Michelangelo\CS\Python\tasks_analysis\CleaningRobot.py", line 155, in obstacle_found
    return GPIO.input(self.INFRARED_PIN) > 0
  File "C:\Users\Michelangelo\AppData\Local\Programs\Python\Python310\lib\unittest\mock.py", line 1104, in __call__
    return self._mock_call(*args, **kwargs)
  File "C:\Users\Michelangelo\AppData\Local\Programs\Python\Python310\lib\unittest\mock.py", line 1108, in _mock_call
    return self._execute_mock_call(*args, **kwargs)
  File "C:\Users\Michelangelo\AppData\Local\Programs\Python\Python310\lib\unittest\mock.py", line 1165, in _execute_mock_call
    result = next(effect)
StopIteration

======================================================================
ERROR: test_move_forward_facing_S_with_obstacle (T2_US04.US04)
----------------------------------------------------------------------
Traceback (most recent call last):
  File "C:\Users\Michelangelo\AppData\Local\Programs\Python\Python310\lib\unittest\mock.py", line 1369, in patched
    return func(*newargs, **newkeywargs)
  File "C:\Users\Michelangelo\CS\Python\tasks_analysis\test\T2_US04.py", line 25, in test_move_forward_facing_S_with_obstacle
    self.assertEqual('(1,1,S)(1,0)', self.robot.execute_command('f'))
  File "C:\Users\Michelangelo\CS\Python\tasks_analysis\CleaningRobot.py", line 148, in execute_command
    return self.robot_status()
  File "C:\Users\Michelangelo\CS\Python\tasks_analysis\CleaningRobot.py", line 71, in robot_status
    if self.obstacle_found():
  File "C:\Users\Michelangelo\CS\Python\tasks_analysis\CleaningRobot.py", line 155, in obstacle_found
    return GPIO.input(self.INFRARED_PIN) > 0
  File "C:\Users\Michelangelo\AppData\Local\Programs\Python\Python310\lib\unittest\mock.py", line 1104, in __call__
    return self._mock_call(*args, **kwargs)
  File "C:\Users\Michelangelo\AppData\Local\Programs\Python\Python310\lib\unittest\mock.py", line 1108, in _mock_call
    return self._execute_mock_call(*args, **kwargs)
  File "C:\Users\Michelangelo\AppData\Local\Programs\Python\Python310\lib\unittest\mock.py", line 1165, in _execute_mock_call
    result = next(effect)
StopIteration

======================================================================
ERROR: test_move_forward_facing_W_with_obstacle (T2_US04.US04)
----------------------------------------------------------------------
Traceback (most recent call last):
  File "C:\Users\Michelangelo\AppData\Local\Programs\Python\Python310\lib\unittest\mock.py", line 1369, in patched
    return func(*newargs, **newkeywargs)
  File "C:\Users\Michelangelo\CS\Python\tasks_analysis\test\T2_US04.py", line 33, in test_move_forward_facing_W_with_obstacle
    self.assertEqual('(1,1,W)(0,1)', self.robot.execute_command('f'))
  File "C:\Users\Michelangelo\CS\Python\tasks_analysis\CleaningRobot.py", line 148, in execute_command
    return self.robot_status()
  File "C:\Users\Michelangelo\CS\Python\tasks_analysis\CleaningRobot.py", line 71, in robot_status
    if self.obstacle_found():
  File "C:\Users\Michelangelo\CS\Python\tasks_analysis\CleaningRobot.py", line 155, in obstacle_found
    return GPIO.input(self.INFRARED_PIN) > 0
  File "C:\Users\Michelangelo\AppData\Local\Programs\Python\Python310\lib\unittest\mock.py", line 1104, in __call__
    return self._mock_call(*args, **kwargs)
  File "C:\Users\Michelangelo\AppData\Local\Programs\Python\Python310\lib\unittest\mock.py", line 1108, in _mock_call
    return self._execute_mock_call(*args, **kwargs)
  File "C:\Users\Michelangelo\AppData\Local\Programs\Python\Python310\lib\unittest\mock.py", line 1165, in _execute_mock_call
    result = next(effect)
StopIteration

======================================================================
FAIL: test_low_battery_no_movement (T2_US05.US05)
----------------------------------------------------------------------
Traceback (most recent call last):
  File "C:\Users\Michelangelo\AppData\Local\Programs\Python\Python310\lib\unittest\mock.py", line 1369, in patched
    return func(*newargs, **newkeywargs)
  File "C:\Users\Michelangelo\CS\Python\tasks_analysis\test\T2_US05.py", line 17, in test_low_battery_no_movement
    self.assertEqual('(0,0,N)', status)
AssertionError: '(0,0,N)' != '(0,0,N)(0,1)'
- (0,0,N)
+ (0,0,N)(0,1)
?        +++++


----------------------------------------------------------------------
Ran 23 tests in 23.197s

FAILED (failures=1, errors=10)
